Workbook

Sheet 業績對照
M2: 大勝 (+ 20%) | N2: =COUNTIF(N9:N62, ">=20%") -> 0 | Q2: 大勝 (+ 20%) | R2: =COUNTIF(R9:R62, ">=20%") -> 10 | U2: 大勝 (+ 20%) | V2: =COUNTIF(V9:V62, ">=20%") -> 9
M3: 小勝 (+ 0-20%) | N3: =COUNTIFS(N9:N62, ">=0%", N9:N62, "<20%") -> 0 | Q3: 小勝 (+ 0-20%) | R3: =COUNTIFS(R9:R62, ">=0%", R9:R62, "<20%") -> 9 | U3: 小勝 (+ 0-20%) | V3: =COUNTIFS(V9:V62, ">=0%", V9:V62, "<20%") -> 8
M4: 小負 (- 0-20%) | N4: =COUNTIFS(N9:N62, "<0%", N9:N62, ">=-20%") -> 0 | Q4: 小負 (- 0-20%) | R4: =COUNTIFS(R9:R62, "<0%", R9:R62, ">=-20%") -> 10 | U4: 小負 (- 0-20%) | V4: =COUNTIFS(V9:V62, "<0%", V9:V62, ">=-20%") -> 8
M5: 大負 (- 20%) | N5: =COUNTIF(N9:N62, "<-20%") -> 0 | Q5: 大負 (- 20%) | R5: =COUNTIF(R9:R62, "<-20%") -> 25 | U5: 大負 (- 20%) | V5: =COUNTIF(V9:V62, "<-20%") -> 28
B7: OWNDAYS門市 | D7: 鄰近Jins門市 | F7: 2026 Apr 1-16 3pm | K7: 2026 Mar | O7: 2026 Feb | S7: 2026 Jan | X7: Draft Discussion: Top 15 Stores Incentives
B8: 編號 | C8: 名稱 | D8: 編號 | E8: 名稱 | F8: OWNDAYS業績 | G8: OWNDAYS MoM (est.) | H8: Jins業績 | I8: Jins MoM (est.) | J8: MoM Trend | K8: OWNDAYS | L8: Jins | M8: Delta$ | N8: Delta% | O8: OWNDAYS | P8: Jins | Q8: Delta$ | R8: Delta% | S8: OWNDAYS | T8: Jins | U8: Delta$ | V8: Delta% | X8: 與Jins Delta進步值 (p.p.) | Y8: 全店每人$ | AA8: No. | AB8: 3月實際
B9: 930 | C9: 漢神巨蛋 | D9: 85064 | E9: JINS漢神巨蛋 | K9: =index(AB:AB,match(B9,AA:AA,0)) -> 4830438 | L9: =index(Jins_Mar!C:C,match(D9,Jins_Mar!A:A,0)) -> #REF! | M9: =iferror(K9-L9,"NA") -> NA | N9: =iferror(K9/L9-1,"") | O9: 6066324 | P9: 4518911 | Q9: =iferror(O9-P9,"NA") -> 1547413 | R9: =iferror(O9/P9-1,"") -> 0.34243051 | S9: 5095327 | T9: 4210981 | U9: =iferror(S9-T9,"NA") -> 884346 | V9: =iferror(S9/T9-1,"") -> 0.2100095 | X9: 10 p.p. | Y9: 1000 | AA9: 940 | AB9: 4917697
B10: 940 | C10: 新竹巨城 | D10: 85031 | E10: JINS新竹Big city店 | K10: =index(AB:AB,match(B10,AA:AA,0)) -> 4917697 | L10: =index(Jins_Mar!C:C,match(D10,Jins_Mar!A:A,0)) -> #REF! | M10: =iferror(K10-L10,"NA") -> NA | N10: =iferror(K10/L10-1,"") | O10: 5499253 | P10: 5272015 | Q10: =iferror(O10-P10,"NA") -> 227238 | R10: =iferror(O10/P10-1,"") -> 0.043102685 | S10: 4541934 | T10: 3959174 | U10: =iferror(S10-T10,"NA") -> 582760 | V10: =iferror(S10/T10-1,"") -> 0.14719232 | X10: 20 p.p. | Y10: 2000 | AA10: 930 | AB10: 4830438
B11: 935 | C11: Mitsui outlet park 林口 | D11: 85075 | E11: JINS林口三井店 | K11: =index(AB:AB,match(B11,AA:AA,0)) -> 3846451 | L11: =index(Jins_Mar!C:C,match(D11,Jins_Mar!A:A,0)) -> #REF! | M11: =iferror(K11-L11,"NA") -> NA | N11: =iferror(K11/L11-1,"") | O11: 5316131 | P11: 3877835 | Q11: =iferror(O11-P11,"NA") -> 1438296 | R11: =iferror(O11/P11-1,"") -> 0.3709018 | S11: 4215537 | T11: 3161640 | U11: =iferror(S11-T11,"NA") -> 1053897 | V11: =iferror(S11/T11-1,"") -> 0.33333871 | X11: 30 p.p. | Y11: 3000 | AA11: 950 | AB11: 4529005
B12: 950 | C12: 南西 | D12: 85002 | E12: JINS三越南西店 | K12: =index(AB:AB,match(B12,AA:AA,0)) -> 4529005 | L12: =index(Jins_Mar!C:C,match(D12,Jins_Mar!A:A,0)) -> #REF! | M12: =iferror(K12-L12,"NA") -> NA | N12: =iferror(K12/L12-1,"") | O12: 4806707 | P12: 6642812 | Q12: =iferror(O12-P12,"NA") -> -1836105 | R12: =iferror(O12/P12-1,"") -> -0.27640478 | S12: 4755888 | T12: 6450518 | U12: =iferror(S12-T12,"NA") -> -1694630 | V12: =iferror(S12/T12-1,"") -> -0.26271223 | X12: 40 p.p. | Y12: 4000 | AA12: 935 | AB12: 3846451
B13: 947 | C13: 大江購物中心 | D13: 85051 | E13: JINS桃園中歴SOGO店 | K13: =index(AB:AB,match(B13,AA:AA,0)) -> 2617220 | L13: =index(Jins_Mar!C:C,match(D13,Jins_Mar!A:A,0)) -> #REF! | M13: =iferror(K13-L13,"NA") -> NA | N13: =iferror(K13/L13-1,"") | O13: 4005020 | P13: 2008100 | Q13: =iferror(O13-P13,"NA") -> 1996920 | R13: =iferror(O13/P13-1,"") -> 0.99443255 | S13: 3176773 | T13: 1589411 | U13: =iferror(S13-T13,"NA") -> 1587362 | V13: =iferror(S13/T13-1,"") -> 0.99871084 | X13: 50 p.p. | Y13: 6000 | AA13: 944 | AB13: 3159091
B14: 944 | C14: 南紡購物中心 | D14: 85034 | E14: JINS南紡購物中心店 | K14: =index(AB:AB,match(B14,AA:AA,0)) -> 3159091 | L14: =index(Jins_Mar!C:C,match(D14,Jins_Mar!A:A,0)) -> #REF! | M14: =iferror(K14-L14,"NA") -> NA | N14: =iferror(K14/L14-1,"") | O14: 3947338 | P14: 5283099 | Q14: =iferror(O14-P14,"NA") -> -1335761 | R14: =iferror(O14/P14-1,"") -> -0.25283664 | S14: 2912103 | T14: 4445310 | U14: =iferror(S14-T14,"NA") -> -1533207 | V14: =iferror(S14/T14-1,"") -> -0.3449044 | AA14: 975 | AB14: 3032286
B15: 1010 | C15: 高雄夢時代 | D15: 85016 | E15: JINS高雄夢時代店 | K15: =index(AB:AB,match(B15,AA:AA,0)) -> 2587139 | L15: =index(Jins_Mar!C:C,match(D15,Jins_Mar!A:A,0)) -> #REF! | M15: =iferror(K15-L15,"NA") -> NA | N15: =iferror(K15/L15-1,"") | O15: 3639313 | P15: 7794404 | Q15: =iferror(O15-P15,"NA") -> -4155091 | R15: =iferror(O15/P15-1,"") -> -0.53308643 | S15: 2838376 | T15: 6519637 | U15: =iferror(S15-T15,"NA") -> -3681261 | V15: =iferror(S15/T15-1,"") -> -0.56464202 | AA15: 966 | AB15: 2832631
B16: 975 | C16: 美麗華 | D16: 85052 | E16: JINS美麗華摩天輪店 | K16: =index(AB:AB,match(B16,AA:AA,0)) -> 3032286 | L16: =index(Jins_Mar!C:C,match(D16,Jins_Mar!A:A,0)) -> #REF! | M16: =iferror(K16-L16,"NA") -> NA | N16: =iferror(K16/L16-1,"") | O16: 3423547 | P16: 2037802 | Q16: =iferror(O16-P16,"NA") -> 1385745 | R16: =iferror(O16/P16-1,"") -> 0.68001945 | S16: 3246961 | T16: 2417231 | U16: =iferror(S16-T16,"NA") -> 829730 | V16: =iferror(S16/T16-1,"") -> 0.3432564 | AA16: 941 | AB16: 2866025
B17: 969 | C17: 基隆東岸廣場 | D17: 85040 | E17: JINS基隆MOYA店 | K17: =index(AB:AB,match(B17,AA:AA,0)) -> 2593738 | L17: =index(Jins_Mar!C:C,match(D17,Jins_Mar!A:A,0)) -> #REF! | M17: =iferror(K17-L17,"NA") -> NA | N17: =iferror(K17/L17-1,"") | O17: 3102147 | P17: 1285561 | Q17: =iferror(O17-P17,"NA") -> 1816586 | R17: =iferror(O17/P17-1,"") -> 1.4130687 | S17: 2617530 | T17: 1341971 | U17: =iferror(S17-T17,"NA") -> 1275559 | V17: =iferror(S17/T17-1,"") -> 0.9505116 | AA17: 947 | AB17: 2617220
B18: 1051 | C18: lalaport南港 | D18: 85081 | E18: RIM台北南港lalaport店 | K18: =index(AB:AB,match(B18,AA:AA,0)) -> 2252348 | L18: =index(Jins_Mar!C:C,match(D18,Jins_Mar!A:A,0)) -> #REF! | M18: =iferror(K18-L18,"NA") -> NA | N18: =iferror(K18/L18-1,"") | O18: 3053514 | P18: 2757937 | Q18: =iferror(O18-P18,"NA") -> 295577 | R18: =iferror(O18/P18-1,"") -> 0.10717322 | S18: 2430695 | T18: 2416428 | U18: =iferror(S18-T18,"NA") -> 14267 | V18: =iferror(S18/T18-1,"") -> 0.0059041693 | AA18: 1010 | AB18: 2587139
B19: 941 | C19: 台北忠孝SOGO | D19: 85005 | E19: JINS太平洋崇光忠孝復興店 | K19: =index(AB:AB,match(B19,AA:AA,0)) -> 2866025 | L19: =index(Jins_Mar!C:C,match(D19,Jins_Mar!A:A,0)) -> #REF! | M19: =iferror(K19-L19,"NA") -> NA | N19: =iferror(K19/L19-1,"") | O19: 3050594 | P19: 3554252 | Q19: =iferror(O19-P19,"NA") -> -503658 | R19: =iferror(O19/P19-1,"") -> -0.14170577 | S19: 2609660 | T19: 3608884 | U19: =iferror(S19-T19,"NA") -> -999224 | V19: =iferror(S19/T19-1,"") -> -0.27687895 | AA19: 925 | AB19: 2679654
B20: 964 | C20: 新光三越信義A11 | D20: 85019 | E20: JINS新光三越信義A8店 | K20: =index(AB:AB,match(B20,AA:AA,0)) -> 2369254 | L20: =index(Jins_Mar!C:C,match(D20,Jins_Mar!A:A,0)) -> #REF! | M20: =iferror(K20-L20,"NA") -> NA | N20: =iferror(K20/L20-1,"") | O20: 3019296 | P20: 3772711 | Q20: =iferror(O20-P20,"NA") -> -753415 | R20: =iferror(O20/P20-1,"") -> -0.19970122 | S20: 2689490 | T20: 3319029 | U20: =iferror(S20-T20,"NA") -> -629539 | V20: =iferror(S20/T20-1,"") -> -0.18967566 | AA20: 981 | AB20: 2617536
B21: 981 | C21: 新店家樂福 | D21: 85062 | E21: JINS誠品新店 | K21: =index(AB:AB,match(B21,AA:AA,0)) -> 2617536 | L21: =index(Jins_Mar!C:C,match(D21,Jins_Mar!A:A,0)) -> #REF! | M21: =iferror(K21-L21,"NA") -> NA | N21: =iferror(K21/L21-1,"") | O21: 2878219 | P21: 4259217 | Q21: =iferror(O21-P21,"NA") -> -1380998 | R21: =iferror(O21/P21-1,"") -> -0.32423753 | S21: 2694906 | T21: 3705960 | U21: =iferror(S21-T21,"NA") -> -1011054 | V21: =iferror(S21/T21-1,"") -> -0.27281838 | AA21: 969 | AB21: 2593738
B22: 966 | C22: 台北天母SOGO | D22: 85027 | E22: JINS高島屋天母店 | K22: =index(AB:AB,match(B22,AA:AA,0)) -> 2832631 | L22: =index(Jins_Mar!C:C,match(D22,Jins_Mar!A:A,0)) -> #REF! | M22: =iferror(K22-L22,"NA") -> NA | N22: =iferror(K22/L22-1,"") | O22: 2850409 | P22: 2727106 | Q22: =iferror(O22-P22,"NA") -> 123303 | R22: =iferror(O22/P22-1,"") -> 0.045213864 | S22: 2834814 | T22: 2496134 | U22: =iferror(S22-T22,"NA") -> 338680 | V22: =iferror(S22/T22-1,"") -> 0.13568182 | AA22: 964 | AB22: 2369254
B23: 1009 | C23: 花蓮遠百 | D23: 85047 | E23: JINS花蓮中山店 | K23: =index(AB:AB,match(B23,AA:AA,0)) -> 2078592 | L23: =index(Jins_Mar!C:C,match(D23,Jins_Mar!A:A,0)) -> #REF! | M23: =iferror(K23-L23,"NA") -> NA | N23: =iferror(K23/L23-1,"") | O23: 2801595 | P23: 2087715 | Q23: =iferror(O23-P23,"NA") -> 713880 | R23: =iferror(O23/P23-1,"") -> 0.34194323 | S23: 2524047 | T23: 1426211 | U23: =iferror(S23-T23,"NA") -> 1097836 | V23: =iferror(S23/T23-1,"") -> 0.76975707 | AA23: 1051 | AB23: 2252348
B24: 939 | C24: 新光三越台南小西門 | D24: 85011 | E24: JINS新光三越台南西門店 | K24: =index(AB:AB,match(B24,AA:AA,0)) -> 1865660 | L24: =index(Jins_Mar!C:C,match(D24,Jins_Mar!A:A,0)) -> #REF! | M24: =iferror(K24-L24,"NA") -> NA | N24: =iferror(K24/L24-1,"") | O24: 2768711 | P24: 3203869 | Q24: =iferror(O24-P24,"NA") -> -435158 | R24: =iferror(O24/P24-1,"") -> -0.13582266 | S24: 2329662 | T24: 2818447 | U24: =iferror(S24-T24,"NA") -> -488785 | V24: =iferror(S24/T24-1,"") -> -0.17342352 | AA24: 923 | AB24: 2233351
B25: 1029 | C25: LaLaport台中 | D25: 85058 | E25: RIM台中三井lalaport店 | K25: =index(AB:AB,match(B25,AA:AA,0)) -> 2229596 | L25: =index(Jins_Mar!C:C,match(D25,Jins_Mar!A:A,0)) -> #REF! | M25: =iferror(K25-L25,"NA") -> NA | N25: =iferror(K25/L25-1,"") | O25: 2738651 | P25: 3033587 | Q25: =iferror(O25-P25,"NA") -> -294936 | R25: =iferror(O25/P25-1,"") -> -0.097223518 | S25: 2334099 | T25: 2240203 | U25: =iferror(S25-T25,"NA") -> 93896 | V25: =iferror(S25/T25-1,"") -> 0.041914059 | AA25: 992 | AB25: 2290476
... B29: 992 | C29: 西門漢中 | D29: 85028 | E29: JINS誠品武昌店 | K29: =index(AB:AB,match(B29,AA:AA,0)) -> 2290476 | L29: =index(Jins_Mar!C:C,match(D29,Jins_Mar!A:A,0)) -> #REF! | M29: =iferror(K29-L29,"NA") -> NA | N29: =iferror(K29/L29-1,"") | O29: 2356705 | P29: 1781463 | Q29: =iferror(O29-P29,"NA") -> 575242 | R29: =iferror(O29/P29-1,"") -> 0.32290426 | S29: 2062112 | T29: 1660175 | U29: =iferror(S29-T29,"NA") -> 401937 | V29: =iferror(S29/T29-1,"") -> 0.2421052 | AA29: 939 | AB29: 1865660
B30: 993 | C30: 秀泰樹林 | D30: 85100 | E30: JINS秀泰樹林店 | K30: =index(AB:AB,match(B30,AA:AA,0)) -> 1586551 | L30: =index(Jins_Mar!C:C,match(D30,Jins_Mar!A:A,0)) -> #REF! | M30: =iferror(K30-L30,"NA") -> NA | N30: =iferror(K30/L30-1,"") | O30: 2276424 | P30: 1184786 | Q30: =iferror(O30-P30,"NA") -> 1091638 | R30: =iferror(O30/P30-1,"") -> 0.92137989 | S30: 1687934 | U30: =iferror(S30-T30,"NA") -> 1687934 | V30: =iferror(S30/T30-1,"") | AA30: 988 | AB30: 1904941
B31: 988 | C31: 秀泰嘉義 | D31: 85093 | E31: JINS耐斯廣場購物中心店 | K31: =index(AB:AB,match(B31,AA:AA,0)) -> 1904941 | L31: =index(Jins_Mar!C:C,match(D31,Jins_Mar!A:A,0)) -> #REF! | M31: =iferror(K31-L31,"NA") -> NA | N31: =iferror(K31/L31-1,"") | O31: 2178318 | P31: 2053140 | Q31: =iferror(O31-P31,"NA") -> 125178 | R31: =iferror(O31/P31-1,"") -> 0.060969052 | S31: 1780920 | T31: 1499305 | U31: =iferror(S31-T31,"NA") -> 281615 | V31: =iferror(S31/T31-1,"") -> 0.18783036 | AA31: 917 | AB31: 1845208
B32: 1025 | C32: 新莊宏匯 | D32: 85096 | E32: JINS宏匯廣場店 | K32: =index(AB:AB,match(B32,AA:AA,0)) -> 1476068 | L32: =index(Jins_Mar!C:C,match(D32,Jins_Mar!A:A,0)) -> #REF! | M32: =iferror(K32-L32,"NA") -> NA | N32: =iferror(K32/L32-1,"") | O32: 2055460 | P32: 2167267 | Q32: =iferror(O32-P32,"NA") -> -111807 | R32: =iferror(O32/P32-1,"") -> -0.051588937 | S32: 1432085 | T32: 1793813 | U32: =iferror(S32-T32,"NA") -> -361728 | V32: =iferror(S32/T32-1,"") -> -0.20165313 | AA32: 946 | AB32: 1720191
B33: 942 | C33: 勤美誠品 | D33: 85078 | E33: JINS誠品綠園道店 | K33: =index(AB:AB,match(B33,AA:AA,0)) -> 1622079 | L33: =index(Jins_Mar!C:C,match(D33,Jins_Mar!A:A,0)) -> #REF! | M33: =iferror(K33-L33,"NA") -> NA | N33: =iferror(K33/L33-1,"") | O33: 1935711 | P33: 2408246 | Q33: =iferror(O33-P33,"NA") -> -472535 | R33: =iferror(O33/P33-1,"") -> -0.19621542 | S33: 1513418 | T33: 2261277 | U33: =iferror(S33-T33,"NA") -> -747859 | V33: =iferror(S33/T33-1,"") -> -0.33072419 | AA33: 1059 | AB33: 1769632
B34: 917 | C34: 微風 台北車站 | D34: 85038 | E34: JINS三越台北駅前店 | K34: =index(AB:AB,match(B34,AA:AA,0)) -> 1845208 | L34: =index(Jins_Mar!C:C,match(D34,Jins_Mar!A:A,0)) -> #REF! | M34: =iferror(K34-L34,"NA") -> NA | N34: =iferror(K34/L34-1,"") | O34: 1926502 | P34: 1696878 | Q34: =iferror(O34-P34,"NA") -> 229624 | R34: =iferror(O34/P34-1,"") -> 0.13532146 | S34: 1848365 | T34: 1742744 | U34: =iferror(S34-T34,"NA") -> 105621 | V34: =iferror(S34/T34-1,"") -> 0.060606148 | AA34: 993 | AB34: 1586551
B35: 1059 | C35: 淡水 | D35: 85069 | E35: JINS淡水英專店 | K35: =index(AB:AB,match(B35,AA:AA,0)) -> 1769632 | L35: =index(Jins_Mar!C:C,match(D35,Jins_Mar!A:A,0)) -> #REF! | M35: =iferror(K35-L35,"NA") -> NA | N35: =iferror(K35/L35-1,"") | O35: 1867641 | P35: 1569845 | Q35: =iferror(O35-P35,"NA") -> 297796 | R35: =iferror(O35/P35-1,"") -> 0.18969771 | S35: 1730181 | T35: 1280606 | U35: =iferror(S35-T35,"NA") -> 449575 | V35: =iferror(S35/T35-1,"") -> 0.35106426 | AA35: 1013 | AB35: 1697137
B36: 956 | C36: 桃園ATT | D36: 85015 | E36: JINS新光三越桃園店 | K36: =index(AB:AB,match(B36,AA:AA,0)) -> 1374697 | L36: =index(Jins_Mar!C:C,match(D36,Jins_Mar!A:A,0)) -> #REF! | M36: =iferror(K36-L36,"NA") -> NA | N36: =iferror(K36/L36-1,"") | O36: 1850307 | P36: 2082217 | Q36: =iferror(O36-P36,"NA") -> -231910 | R36: =iferror(O36/P36-1,"") -> -0.11137648 | S36: 1383907 | T36: 1681076 | U36: =iferror(S36-T36,"NA") -> -297169 | V36: =iferror(S36/T36-1,"") -> -0.17677309 | AA36: 1056 | AB36: 1790304
B37: 973 | C37: 環球板橋 | D37: 85043 | E37: JINS三猿広場店 | K37: =index(AB:AB,match(B37,AA:AA,0)) -> 1339409 | L37: =index(Jins_Mar!C:C,match(D37,Jins_Mar!A:A,0)) -> #REF! | M37: =iferror(K37-L37,"NA") -> NA | N37: =iferror(K37/L37-1,"") | O37: 1835538 | P37: 1682875 | Q37: =iferror(O37-P37,"NA") -> 152663 | R37: =iferror(O37/P37-1,"") -> 0.090715591 | S37: 1395494 | T37: 1606885 | U37: =iferror(S37-T37,"NA") -> -211391 | V37: =iferror(S37/T37-1,"") -> -0.13155328 | AA37: 932 | AB37: 1678146
B38: 973 | C38: 環球板橋 | D38: 85007 | E38: JINS板橋大遠百店 | K38: =index(AB:AB,match(B38,AA:AA,0)) -> 1339409 | L38: =index(Jins_Mar!C:C,match(D38,Jins_Mar!A:A,0)) -> #REF! | M38: =iferror(K38-L38,"NA") -> NA | N38: =iferror(K38/L38-1,"") | O38: 1835538 | P38: 6311519 | Q38: =iferror(O38-P38,"NA") -> -4475981 | R38: =iferror(O38/P38-1,"") -> -0.70917651 | S38: 1395494 | T38: 5591789 | U38: =iferror(S38-T38,"NA") -> -4196295 | V38: =iferror(S38/T38-1,"") -> -0.75043872 | AA38: 1003 | AB38: 1750309
B39: 995 | C39: JC PARK新莊 | D39: 85066 | E39: JINSJCPARK新莊幸福店 | K39: =index(AB:AB,match(B39,AA:AA,0)) -> 1383312 | L39: =index(Jins_Mar!C:C,match(D39,Jins_Mar!A:A,0)) -> #REF! | M39: =iferror(K39-L39,"NA") -> NA | N39: =iferror(K39/L39-1,"") | O39: 1803146 | P39: 1911990 | Q39: =iferror(O39-P39,"NA") -> -108844 | R39: =iferror(O39/P39-1,"") -> -0.056927076 | S39: 1436643 | T39: 1559644 | U39: =iferror(S39-T39,"NA") -> -123001 | V39: =iferror(S39/T39-1,"") -> -0.078864792 | AA39: 942 | AB39: 1622079
B40: 1018 | C40: 新竹大魯閣 | D40: 85079 | E40: JINS新竹湳雅店 | K40: =index(AB:AB,match(B40,AA:AA,0)) -> 1545752 | L40: =index(Jins_Mar!C:C,match(D40,Jins_Mar!A:A,0)) -> #REF! | M40: =iferror(K40-L40,"NA") -> NA | N40: =iferror(K40/L40-1,"") | O40: 1785683 | P40: 1164525 | Q40: =iferror(O40-P40,"NA") -> 621158 | R40: =iferror(O40/P40-1,"") -> 0.53340031 | S40: 1644806 | T40: 1088569 | U40: =iferror(S40-T40,"NA") -> 556237 | V40: =iferror(S40/T40-1,"") -> 0.51098001 | AA40: 1001 | AB40: 1566856
B41: 1056 | C41: 統一夢廣場 | D41: 85003 | E41: JINS統一阪急台北店 | K41: =index(AB:AB,match(B41,AA:AA,0)) -> 1790304 | L41: =index(Jins_Mar!C:C,match(D41,Jins_Mar!A:A,0)) -> #REF! | M41: =iferror(K41-L41,"NA") -> NA | N41: =iferror(K41/L41-1,"") | O41: 1670163 | P41: 4099656 | Q41: =iferror(O41-P41,"NA") -> -2429493 | R41: =iferror(O41/P41-1,"") -> -0.59260899 | S41: 1579621 | T41: 3766613 | U41: =iferror(S41-T41,"NA") -> -2186992 | V41: =iferror(S41/T41-1,"") -> -0.58062562 | AA41: 1018 | AB41: 1545752
B42: 1012 | C42: 遠百竹北 | D42: 85046 | E42: JINS遠東新世紀購物中心店 | K42: =index(AB:AB,match(B42,AA:AA,0)) -> 1630757 | L42: =index(Jins_Mar!C:C,match(D42,Jins_Mar!A:A,0)) -> #REF! | M42: =iferror(K42-L42,"NA") -> NA | N42: =iferror(K42/L42-1,"") | O42: 1664676 | P42: 2951839 | Q42: =iferror(O42-P42,"NA") -> -1287163 | R42: =iferror(O42/P42-1,"") -> -0.43605461 | S42: 1478603 | T42: 2330485 | U42: =iferror(S42-T42,"NA") -> -851882 | V42: =iferror(S42/T42-1,"") -> -0.3655385 | AA42: 921 | AB42: 1566321
... B60: 1060 | C60: 新光三越嘉義 | D60: 85057 | E60: JINS嘉義遠東店 | K60: =index(AB:AB,match(B60,AA:AA,0)) -> 396369 | L60: =index(Jins_Mar!C:C,match(D60,Jins_Mar!A:A,0)) -> #REF! | M60: =iferror(K60-L60,"NA") -> NA | N60: =iferror(K60/L60-1,"") | O60: 605030 | P60: 1039981 | Q60: =iferror(O60-P60,"NA") -> -434951 | R60: =iferror(O60/P60-1,"") -> -0.41822976 | S60: 515881 | T60: 925513 | U60: =iferror(S60-T60,"NA") -> -409632 | V60: =iferror(S60/T60-1,"") -> -0.44259994 | AA60: 1031 | AB60: 1113837
B61: 1068 | C61: 環球中和 | D61: 85014 | E61: JINS環球購物中心中和店 | K61: NA | L61: =index(Jins_Mar!C:C,match(D61,Jins_Mar!A:A,0)) -> #REF! | M61: =iferror(K61-L61,"NA") -> NA | N61: =iferror(K61/L61-1,"") | O61: 0 | P61: 4774781 | Q61: =iferror(O61-P61,"NA") -> -4774781 | R61: =iferror(O61/P61-1,"") -> -1 | S61: 0 | T61: 3917777 | U61: =iferror(S61-T61,"NA") -> -3917777 | V61: =iferror(S61/T61-1,"") -> -1 | AA61: 996 | AB61: 1106839
B62: 1054 | C62: 大巨蛋SOGO | D62: 85084 | E62: JINS台北大巨蛋店 | K62: NA | L62: =index(Jins_Mar!C:C,match(D62,Jins_Mar!A:A,0)) -> #REF! | M62: =iferror(K62-L62,"NA") -> NA | N62: =iferror(K62/L62-1,"") | O62: 0 | P62: 1338227 | Q62: =iferror(O62-P62,"NA") -> -1338227 | R62: =iferror(O62/P62-1,"") -> -1 | S62: 0 | T62: 1420701 | U62: =iferror(S62-T62,"NA") -> -1420701 | V62: =iferror(S62/T62-1,"") -> -1 | AA62: 987 | AB62: 1066621
...
